<?xml version="1.0" ?>
<!-- =================================================================================== -->
<!-- |    This document was autogenerated by xacro from myrobot.urdf.xacro             | -->
<!-- |    EDITING THIS FILE BY HAND IS NOT RECOMMENDED                                 | -->
<!-- =================================================================================== -->
<robot name="robot_name">
  <material name="blue">
    <color rgba="0 0 0.8 1"/>
  </material>
  <material name="grey">
    <color rgba="0.9 0.95 0.95 1.0"/>
  </material>
  <material name="black">
    <color rgba="0 0 0 1"/>
  </material>
  <material name="green">
    <color rgba="0.0 0.8 0.0 1.0"/>
  </material>
  <!-- Root Link -->
  <link name="base_footprint">
    </link>
  <link name="base_link">
    </link>
  <joint name="base_foot_to_base_link" type="fixed">
    <parent link="base_link"/>
    <child link="base_footprint"/>
    <origin rpy="0.0 0.0 0.0" xyz="0.0 0.0 0.0"/>
  </joint>
  <link name="base">
    <visual>
      <origin rpy="0.0 0.0 0.0" xyz="0.0 0.0 0"/>
      <geometry>
        <mesh filename="file:///home/manoj/ros/robot_ws/install/myrobot_description/share/myrobot_description/meshes/base.stl" scale="1 1 1"/>
      </geometry>
      <material name="grey"/>
    </visual>
    <collision>
      <geometry>
        <box size="0.76 0.485 0.18"/>
      </geometry>
    </collision>
    <inertial>
      <mass value="15.0"/>
      <origin rpy="0 0 0" xyz="0 0 0"/>
      <inertia ixx="0.33453125" ixy="0.0" ixz="0.0" iyy="0.7625000000000001" iyz="0.0" izz="1.01603125"/>
    </inertial>
  </link>
  <link name="front_right_wheel">
    <visual>
      <origin rpy="0 0 0" xyz="0 0 0"/>
      <geometry>
        <!-- <mesh filename="package://myrobot_description/meshes/blue_tyre.stl"
                        scale="${scale_stl}" /> -->
        <mesh filename="file:///home/manoj/ros/robot_ws/install/myrobot_description/share/myrobot_description/meshes/blue_tyre.stl" scale="1 1 1"/>
      </geometry>
      <material name="black"/>
    </visual>
    <collision>
      <origin rpy="0 0 0" xyz="0 0 0"/>
      <geometry>
        <!-- <cylinder radius="${wheel_radius}" length="${wheel_thickness}" /> -->
        <mesh filename="file:///home/manoj/ros/robot_ws/install/myrobot_description/share/myrobot_description/meshes/blue_tyre.stl" scale="1 1 1"/>
      </geometry>
    </collision>
    <inertial>
      <mass value="1.0"/>
      <origin rpy="0 0 0" xyz="0 0 0"/>
      <inertia ixx="0.010833333333333335" ixy="0" ixz="0" iyy="0.020000000000000004" iyz="0" izz="0.010833333333333335"/>
    </inertial>
  </link>
  <gazebo reference="front_right_wheel">
    <material>Gazebo/Black</material>
    <mu1 value="0.8"/>
    <mu2 value="0.65"/>
  </gazebo>
  <link name="front_left_wheel">
    <visual>
      <origin rpy="0 0 0" xyz="0 0 0"/>
      <geometry>
        <!-- <mesh filename="package://myrobot_description/meshes/blue_tyre.stl"
                        scale="${scale_stl}" /> -->
        <mesh filename="file:///home/manoj/ros/robot_ws/install/myrobot_description/share/myrobot_description/meshes/blue_tyre.stl" scale="1 1 1"/>
      </geometry>
      <material name="black"/>
    </visual>
    <collision>
      <origin rpy="0 0 0" xyz="0 0 0"/>
      <geometry>
        <!-- <cylinder radius="${wheel_radius}" length="${wheel_thickness}" /> -->
        <mesh filename="file:///home/manoj/ros/robot_ws/install/myrobot_description/share/myrobot_description/meshes/blue_tyre.stl" scale="1 1 1"/>
      </geometry>
    </collision>
    <inertial>
      <mass value="1.0"/>
      <origin rpy="0 0 0" xyz="0 0 0"/>
      <inertia ixx="0.010833333333333335" ixy="0" ixz="0" iyy="0.020000000000000004" iyz="0" izz="0.010833333333333335"/>
    </inertial>
  </link>
  <gazebo reference="front_left_wheel">
    <material>Gazebo/Black</material>
    <mu1 value="0.8"/>
    <mu2 value="0.65"/>
  </gazebo>
  <link name="rear_right_wheel">
    <visual>
      <origin rpy="0 0 0" xyz="0 0 0"/>
      <geometry>
        <!-- <mesh filename="package://myrobot_description/meshes/blue_tyre.stl"
                        scale="${scale_stl}" /> -->
        <mesh filename="file:///home/manoj/ros/robot_ws/install/myrobot_description/share/myrobot_description/meshes/blue_tyre.stl" scale="1 1 1"/>
      </geometry>
      <material name="black"/>
    </visual>
    <collision>
      <origin rpy="0 0 0" xyz="0 0 0"/>
      <geometry>
        <!-- <cylinder radius="${wheel_radius}" length="${wheel_thickness}" /> -->
        <mesh filename="file:///home/manoj/ros/robot_ws/install/myrobot_description/share/myrobot_description/meshes/blue_tyre.stl" scale="1 1 1"/>
      </geometry>
    </collision>
    <inertial>
      <mass value="1.0"/>
      <origin rpy="0 0 0" xyz="0 0 0"/>
      <inertia ixx="0.010833333333333335" ixy="0" ixz="0" iyy="0.020000000000000004" iyz="0" izz="0.010833333333333335"/>
    </inertial>
  </link>
  <gazebo reference="rear_right_wheel">
    <material>Gazebo/Black</material>
    <mu1 value="0.8"/>
    <mu2 value="0.65"/>
  </gazebo>
  <link name="rear_left_wheel">
    <visual>
      <origin rpy="0 0 0" xyz="0 0 0"/>
      <geometry>
        <!-- <mesh filename="package://myrobot_description/meshes/blue_tyre.stl"
                        scale="${scale_stl}" /> -->
        <mesh filename="file:///home/manoj/ros/robot_ws/install/myrobot_description/share/myrobot_description/meshes/blue_tyre.stl" scale="1 1 1"/>
      </geometry>
      <material name="black"/>
    </visual>
    <collision>
      <origin rpy="0 0 0" xyz="0 0 0"/>
      <geometry>
        <!-- <cylinder radius="${wheel_radius}" length="${wheel_thickness}" /> -->
        <mesh filename="file:///home/manoj/ros/robot_ws/install/myrobot_description/share/myrobot_description/meshes/blue_tyre.stl" scale="1 1 1"/>
      </geometry>
    </collision>
    <inertial>
      <mass value="1.0"/>
      <origin rpy="0 0 0" xyz="0 0 0"/>
      <inertia ixx="0.010833333333333335" ixy="0" ixz="0" iyy="0.020000000000000004" iyz="0" izz="0.010833333333333335"/>
    </inertial>
  </link>
  <gazebo reference="rear_left_wheel">
    <material>Gazebo/Black</material>
    <mu1 value="0.8"/>
    <mu2 value="0.65"/>
  </gazebo>
  <!-- Joints remain the same -->
  <joint name="base_link_to_base" type="fixed">
    <parent link="base_link"/>
    <child link="base"/>
    <origin rpy="0.0 0.0 0.0" xyz="0.0 0.0 0.2"/>
  </joint>
  <joint name="front_right_wheel_joint" type="continuous">
    <origin rpy="0 0 0" xyz="0.21 -0.35 0"/>
    <parent link="base"/>
    <child link="front_right_wheel"/>
    <axis xyz="0 1 0"/>
  </joint>
  <joint name="front_left_wheel_joint" type="continuous">
    <origin rpy="0 0 3.1415926" xyz="0.21 0.35 0"/>
    <parent link="base"/>
    <child link="front_left_wheel"/>
    <axis xyz="0 -1 0"/>
  </joint>
  <joint name="rear_right_wheel_joint" type="continuous">
    <origin rpy="0 0 0" xyz="-0.21 -0.35 0"/>
    <parent link="base"/>
    <child link="rear_right_wheel"/>
    <axis xyz="0 1 0"/>
  </joint>
  <joint name="rear_left_wheel_joint" type="continuous">
    <origin rpy="0 0 -3.1415926" xyz="-0.21 0.35 0"/>
    <parent link="base"/>
    <child link="rear_left_wheel"/>
    <axis xyz="0 -1 0"/>
  </joint>
  <!-- Lidar link -->
  <link name="laser">
    <visual>
      <origin rpy="0 0 0" xyz="0 0 0"/>
      <geometry>
        <mesh filename="file:///home/manoj/ros/robot_ws/install/myrobot_description/share/myrobot_description/meshes/mid_360.stl" scale="1 1 1"/>
      </geometry>
      <material name="blue"/>
    </visual>
    <collision>
      <geometry>
        <cylinder length="0.04" radius="0.05"/>
      </geometry>
    </collision>
    <inertial>
      <mass value="0.5"/>
      <origin rpy="0 0 0" xyz="0 0 0"/>
      <inertia ixx="0.0001" ixy="0" ixz="0" iyy="0.0001" iyz="0" izz="0.0001"/>
    </inertial>
  </link>
  <joint name="laser_joint" type="fixed">
    <origin rpy="0 0 0" xyz="0.363 0 0.239"/>
    <parent link="base"/>
    <child link="laser"/>
  </joint>
  <gazebo reference="laser">
    <material>Gazebo/Red</material>
    <sensor name="laser" type="ray">
      <pose> 0 0 0 0 0 0 </pose>
      <visualize>false</visualize>
      <update_rate>10</update_rate>
      <ray>
        <scan>
          <horizontal>
            <samples>360</samples>
            <min_angle>-3.14</min_angle>
            <max_angle>3.14</max_angle>
          </horizontal>
          <vertical>
            <samples>90</samples>
            <resolution>1</resolution>
            <min_angle>-0.12</min_angle>
            <max_angle>0.9</max_angle>
          </vertical>
        </scan>
        <range>
          <min>0.3</min>
          <max>30</max>
        </range>
        <noise>
          <type>gaussian</type>
          <mean>0.0</mean>
          <stddev>0.01</stddev>
          <!-- Default is nonzero -->
        </noise>
      </ray>
      <plugin filename=" " name="laser_controller">
        <ros>
          <!-- <argument>~/out:=sim_lidar/pcd2</argument> -->
          <argument>~/out:=livox/lidar/pcd2</argument>
        </ros>
        <output_type>sensor_msgs/PointCloud2</output_type>
        <frame_name>laser</frame_name>
      </plugin>
    </sensor>
  </gazebo>
  <gazebo>
    <plugin filename="libgazebo_ros_diff_drive.so" name="differential_drive_controller">
      <!-- wheels -->
      <num_wheel_pairs>2</num_wheel_pairs>
      <left_joint>front_left_wheel_joint</left_joint>
      <right_joint>front_right_wheel_joint</right_joint>
      <left_joint>rear_left_wheel_joint</left_joint>
      <right_joint>rear_right_wheel_joint</right_joint>
      <!-- kinematics -->
      <wheel_separation> 0.64</wheel_separation>
      <wheel_separation>0.64</wheel_separation>
      <wheel_diameter>0.4</wheel_diameter>
      <wheel_diameter>0.4</wheel_diameter>
      <!-- Update rate in Hz -->
      <updateRate>10</updateRate>
      <publishRate>30</publishRate>
      <!-- limits -->
      <max_wheel_torque>20</max_wheel_torque>
      <max_wheel_acceleration>5</max_wheel_acceleration>
      <!-- input -->
      <command_topic>cmd_vel</command_topic>
      <!-- output -->
      <publish_odom>true</publish_odom>
      <publish_odom_tf>true</publish_odom_tf>
      <publish_wheel_tf>true</publish_wheel_tf>
      <odometry_frame>odom</odometry_frame>
      <odometry_topic>odom</odometry_topic>
      <robot_base_frame>base_link</robot_base_frame>
    </plugin>
  </gazebo>
  <link name="imu_link"/>
  <joint name="imu_to_base_link" type="fixed">
    <parent link="base"/>
    <child link="imu_link"/>
    <origin rpy="0 0 0" xyz="0.363 0 0.239"/>
  </joint>
  <gazebo reference="imu_link">
    <gravity>true</gravity>
    <sensor name="imu_sensor" type="imu">
      <always_on>true</always_on>
      <update_rate>20</update_rate>
      <visualize>true</visualize>
      <topic>__default_topic__</topic>
      <plugin filename="libgazebo_ros_imu_sensor.so" name="imu_plugin">
        <ros>
          <remapping>~/out:=livox/imu</remapping>
        </ros>
        <topicName>livox/imu</topicName>
        <bodyName>imu_link</bodyName>
        <updateRateHZ>10.0</updateRateHZ>
        <gaussianNoise>0.0</gaussianNoise>
        <xyzOffset>0 0 0</xyzOffset>
        <rpyOffset>0 0 0</rpyOffset>
        <frameName>imu_link</frameName>
        <initialOrientationAsReference>false</initialOrientationAsReference>
      </plugin>
      <pose>0 0 0 0 0 0</pose>
    </sensor>
  </gazebo>
</robot>
